Workbook

Sheet Raw Data
A1: CT | B1: 2021 | C1: 2022 | D1: 2023 | E1: 2024 | F1: 2025
A2: Income Statement
A3: Revenue | B3: 16292.1 | C3: 17810.6 | D3: 16656.5 | E3: 16357.8 | F3: 16315.5
A4: Cost of Sales | B4: 9794.4 | C4: 11712.7 | D4: 10952.9 | E4: 10739.1 | F4: 10700.2
A5: Gross Profit | B5: 5076.6 | C5: 6097.9 | D5: 5703.6 | E5: 5618.7 | F5: 5615.3
A6: Operating Income | B6: 1429.6 | C6: 1814.8 | D6: 913.4 | E6: 1774.2 | F6: 1674.6
A7: Interest Expense (or Net Finance Costs) | B7: 256.5 | C7: 231 | D7: 321.5 | E7: 349 | F7: 295.5
A8: Income Before Tax | B8: 1172.1 | C8: 1583.8 | D8: 572.8 | E8: 1246 | F8: 878.5
A9: Income Tax Expense | B9: 309.5 | C9: 401 | D9: 233.7 | E9: 274.1 | F9: 219.5
A10: Net Income | B10: 1260.7 | C10: 1182.8 | D10: 339.1 | E10: 971.9 | F10: 609.7
A11: Balance Sheet – Assets
A12: Cash & Cash Equivalents | B12: 1327.2 | C12: 331.3 | D12: 311.2 | E12: 475.6 | F12: 553.5
A13: Trade Receivables | B13: 973.6 | C13: 1309.9 | D13: 1151.3 | E13: 1263 | F13: 1053.2
A14: Inventory | B14: 2312.9 | C14: 3216.1 | D14: 2693.7 | E14: 2558.3 | F14: 2417.5
A15: Total Current Assets | B15: 10546.8 | C15: 11530.4 | D15: 11293.1 | E15: 11347.9 | F15: 11316.3
A16: Property & Equipment (Net PPE) | B16: 4298.2 | C16: 4994.1 | D16: 5219.5 | E16: 5394.4 | F16: 5522.8
A17: Goodwill | B17: 889.5 | C17: 863.2 | D17: 844.8 | E17: 838.7 | F17: 491.1
A18: Intangible Assets | B18: 1483.3 | C18: 1478.4 | D18: 1409.9 | E18: 1337.5 | F18: 870
A19: Total Assets | B19: 20377.1 | C19: 22102.3 | D19: 21978.3 | E19: 22240.6 | F19: 21539.8
A20: Balance Sheet – Liabilities
A21: Accounts Payable | B21: 2508.3 | C21: 3200.9 | D21: 2689.4 | E21: 2931.4 | F21: 2811.6
A22: Short-Term Borrowings (if shown) | B22: 165.4 | C22: 576.2 | D22: 965.7 | E22: 295.8 | F22: 295.1
A23: Current Portion of Long-Term Debt | B23: 150.5 | C23: 1040.2 | D23: 560.5 | E23: 680.4 | F23: 758
A24: Total Current Liabilities | B24: 5205.8 | C24: 7147 | D24: 6389 | E24: 6335.4 | F24: 6196.5
A25: Long-Term Debt | B25: 4115.7 | C25: 3217.5 | D25: 4404 | E25: 3875.5 | F25: 3617.9
A26: Total Liabilities | B26: 14542.4 | C26: 15063.1 | D26: 15533.5 | E26: 15152.3 | F26: 14725.9
A27: Balance Sheet – Equity
A28: Retained Earnings | B28: 4136.9 | C28: 5070.2 | D28: 5128.2 | E28: 5614.4 | F28: 5230.3
A29: Total Shareholders’ Equity | B29: 4499.1 | C29: 5618.5 | D29: 5545.1 | E29: 6155 | F29: 5855.6
A30: Total Equity | B30: 5834.7 | C30: 7039.2 | D30: 6444.8 | E30: 7088.3 | F30: 6813.9
A31: Cash Flow Statement
A32: Cash From Operating Activities | B32: 2442.8 | C32: 566 | D32: 1353.7 | E32: 2063.8 | F32: 952.1
A33: Capital Expenditures | B33: 436.5 | C33: 834.6 | D33: 580.9 | E33: 576.3 | F33: 582
A34: Depreciation Expense | B34: 582.6 | C34: 621 | D34: 675.2 | E34: 664.9 | F34: 653.9
A35: Dividends Paid | B35: 262.9 | C35: 325.8 | D35: 360.8 | E35: 359.8 | F35: 361.7
A36: PPE Note
A37: Gross PPE | B37: 7865.5 | C37: 8997.7 | D37: 9444.5 | E37: 9770.4 | F37: 10123.6
A38: Accumulated Depreciation | B38: 3567.3 | C38: 4003.6 | D38: 4225 | E38: 4376 | F38: 4600.8
A39: Net PPE | B39: 4298.2 | C39: 4994.1 | D39: 5219.5 | E39: 5394.4 | F39: 5522.8

Sheet Ratios
A1: CT Ratio | B1: 2021 | C1: 2022 | D1: 2023 | E1: 2024 | F1: 2025 | G1: Category
A2: Revenue Growth | C2: =IFERROR('Raw Data'!C3/'Raw Data'!B3-1,"") -> 0.093204682 | D2: =IFERROR('Raw Data'!D3/'Raw Data'!C3-1,"") -> -0.064798491 | E2: =IFERROR('Raw Data'!E3/'Raw Data'!D3-1,"") -> -0.017932939 | F2: =IFERROR('Raw Data'!F3/'Raw Data'!E3-1,"") -> -0.0025859223 | G2: Growth
A3: Gross Margin | B3: ='Raw Data'!B5/'Raw Data'!B3 -> 0.31159887 | C3: ='Raw Data'!C5/'Raw Data'!C3 -> 0.34237477 | D3: ='Raw Data'!D5/'Raw Data'!D3 -> 0.34242488 | E3: ='Raw Data'!E5/'Raw Data'!E3 -> 0.34348751 | F3: ='Raw Data'!F5/'Raw Data'!F3 -> 0.34416965 | G3: Profitability
A4: Operating Margin | B4: ='Raw Data'!B6/'Raw Data'!B3 -> 0.08774805 | C4: ='Raw Data'!C6/'Raw Data'!C3 -> 0.10189438 | D4: ='Raw Data'!D6/'Raw Data'!D3 -> 0.054837451 | E4: ='Raw Data'!E6/'Raw Data'!E3 -> 0.10846202 | F4: ='Raw Data'!F6/'Raw Data'!F3 -> 0.1026386 | G4: Profitability
A5: Net Margin | B5: ='Raw Data'!B10/'Raw Data'!B3 -> 0.077381062 | C5: ='Raw Data'!C10/'Raw Data'!C3 -> 0.066409891 | D5: ='Raw Data'!D10/'Raw Data'!D3 -> 0.020358419 | E5: ='Raw Data'!E10/'Raw Data'!E3 -> 0.05941508 | F5: ='Raw Data'!F10/'Raw Data'!F3 -> 0.037369373 | G5: Profitability
A6: Current Ratio | B6: ='Raw Data'!B15/'Raw Data'!B24 -> 2.025971 | C6: ='Raw Data'!C15/'Raw Data'!C24 -> 1.6133203 | D6: ='Raw Data'!D15/'Raw Data'!D24 -> 1.7675849 | E6: ='Raw Data'!E15/'Raw Data'!E24 -> 1.7911892 | F6: ='Raw Data'!F15/'Raw Data'!F24 -> 1.8262406 | G6: Liquidity
A7: Quick Ratio | B7: =('Raw Data'!B12+'Raw Data'!B13)/'Raw Data'!B24 -> 0.44196857 | C7: =('Raw Data'!C12+'Raw Data'!C13)/'Raw Data'!C24 -> 0.22963481 | D7: =('Raw Data'!D12+'Raw Data'!D13)/'Raw Data'!D24 -> 0.22890906 | E7: =('Raw Data'!E12+'Raw Data'!E13)/'Raw Data'!E24 -> 0.27442624 | F7: =('Raw Data'!F12+'Raw Data'!F13)/'Raw Data'!F24 -> 0.25929154 | G7: Liquidity
A8: Debt Ratio | B8: ='Raw Data'!B26/'Raw Data'!B19 -> 0.71366387 | C8: ='Raw Data'!C26/'Raw Data'!C19 -> 0.68151731 | D8: ='Raw Data'!D26/'Raw Data'!D19 -> 0.70676531 | E8: ='Raw Data'!E26/'Raw Data'!E19 -> 0.68129007 | F8: ='Raw Data'!F26/'Raw Data'!F19 -> 0.68366002 | G8: Solvency
A9: Debt-to-Equity | B9: ='Raw Data'!B26/'Raw Data'!B30 -> 2.4923989 | C9: ='Raw Data'!C26/'Raw Data'!C30 -> 2.1398881 | D9: ='Raw Data'!D26/'Raw Data'!D30 -> 2.4102377 | E9: ='Raw Data'!E26/'Raw Data'!E30 -> 2.1376494 | F9: ='Raw Data'!F26/'Raw Data'!F30 -> 2.1611559 | G9: Solvency
A10: ROA | C10: ='Raw Data'!C10/AVERAGE('Raw Data'!B19,'Raw Data'!C19) -> 0.055688169 | D10: ='Raw Data'!D10/AVERAGE('Raw Data'!C19,'Raw Data'!D19) -> 0.015385453 | E10: ='Raw Data'!E10/AVERAGE('Raw Data'!D19,'Raw Data'!E19) -> 0.043958579 | F10: ='Raw Data'!F10/AVERAGE('Raw Data'!E19,'Raw Data'!F19) -> 0.027852646 | G10: Profitability
A11: ROE | C11: ='Raw Data'!C10/AVERAGE('Raw Data'!B30,'Raw Data'!C30) -> 0.18375162 | D11: ='Raw Data'!D10/AVERAGE('Raw Data'!C30,'Raw Data'!D30) -> 0.050296648 | E11: ='Raw Data'!E10/AVERAGE('Raw Data'!D30,'Raw Data'!E30) -> 0.14363302 | F11: ='Raw Data'!F10/AVERAGE('Raw Data'!E30,'Raw Data'!F30) -> 0.087712736 | G11: Profitability
A12: Asset Turnover | C12: ='Raw Data'!C3/AVERAGE('Raw Data'!B19,'Raw Data'!C19) -> 0.83855233 | D12: ='Raw Data'!D3/AVERAGE('Raw Data'!C19,'Raw Data'!D19) -> 0.75572928 | E12: ='Raw Data'!E3/AVERAGE('Raw Data'!D19,'Raw Data'!E19) -> 0.73985558 | F12: ='Raw Data'!F3/AVERAGE('Raw Data'!E19,'Raw Data'!F19) -> 0.74533353 | G12: Efficiency
A13: Inventory Turnover | C13: ='Raw Data'!C4/AVERAGE('Raw Data'!B14,'Raw Data'!C14) -> 4.236824 | D13: ='Raw Data'!D4/AVERAGE('Raw Data'!C14,'Raw Data'!D14) -> 3.7066906 | E13: ='Raw Data'!E4/AVERAGE('Raw Data'!D14,'Raw Data'!E14) -> 4.0895278 | F13: ='Raw Data'!F4/AVERAGE('Raw Data'!E14,'Raw Data'!F14) -> 4.3008963 | G13: Efficiency
A14: OCF / Net Income | B14: ='Raw Data'!B32/'Raw Data'!B10 -> 1.9376537 | C14: ='Raw Data'!C32/'Raw Data'!C10 -> 0.47852553 | D14: ='Raw Data'!D32/'Raw Data'!D10 -> 3.9920377 | E14: ='Raw Data'!E32/'Raw Data'!E10 -> 2.1234695 | F14: ='Raw Data'!F32/'Raw Data'!F10 -> 1.5615877 | G14: Cash Flow
A15: Free Cash Flow | B15: ='Raw Data'!B32-'Raw Data'!B33 -> 2006.3 | C15: ='Raw Data'!C32-'Raw Data'!C33 -> -268.6 | D15: ='Raw Data'!D32-'Raw Data'!D33 -> 772.8 | E15: ='Raw Data'!E32-'Raw Data'!E33 -> 1487.5 | F15: ='Raw Data'!F32-'Raw Data'!F33 -> 370.1 | G15: Cash Flow

Sheet Trend Analysis
A1: CT Item | B1: 2021 | C1: 2022 | D1: 2023 | E1: 2024 | F1: 2025
A2: Revenue | C2: =IFERROR('Raw Data'!C3/'Raw Data'!B3-1,"") -> 0.093204682 | D2: =IFERROR('Raw Data'!D3/'Raw Data'!C3-1,"") -> -0.064798491 | E2: =IFERROR('Raw Data'!E3/'Raw Data'!D3-1,"") -> -0.017932939 | F2: =IFERROR('Raw Data'!F3/'Raw Data'!E3-1,"") -> -0.0025859223
A3: Gross Profit | C3: =IFERROR('Raw Data'!C5/'Raw Data'!B5-1,"") -> 0.20117795 | D3: =IFERROR('Raw Data'!D5/'Raw Data'!C5-1,"") -> -0.064661605 | E3: =IFERROR('Raw Data'!E5/'Raw Data'!D5-1,"") -> -0.014885336 | F3: =IFERROR('Raw Data'!F5/'Raw Data'!E5-1,"") -> -0.00060512218
A4: Operating Income | C4: =IFERROR('Raw Data'!C6/'Raw Data'!B6-1,"") -> 0.269446 | D4: =IFERROR('Raw Data'!D6/'Raw Data'!C6-1,"") -> -0.49669385 | E4: =IFERROR('Raw Data'!E6/'Raw Data'!D6-1,"") -> 0.94241296 | F4: =IFERROR('Raw Data'!F6/'Raw Data'!E6-1,"") -> -0.056137978
A5: Net Income | C5: =IFERROR('Raw Data'!C10/'Raw Data'!B10-1,"") -> -0.061791068 | D5: =IFERROR('Raw Data'!D10/'Raw Data'!C10-1,"") -> -0.71330741 | E5: =IFERROR('Raw Data'!E10/'Raw Data'!D10-1,"") -> 1.8661162 | F5: =IFERROR('Raw Data'!F10/'Raw Data'!E10-1,"") -> -0.37267209
A6: Total Assets | C6: =IFERROR('Raw Data'!C19/'Raw Data'!B19-1,"") -> 0.084663667 | D6: =IFERROR('Raw Data'!D19/'Raw Data'!C19-1,"") -> -0.0056102759 | E6: =IFERROR('Raw Data'!E19/'Raw Data'!D19-1,"") -> 0.011934499 | F6: =IFERROR('Raw Data'!F19/'Raw Data'!E19-1,"") -> -0.031509941
A7: Total Liabilities | C7: =IFERROR('Raw Data'!C26/'Raw Data'!B26-1,"") -> 0.035805644 | D7: =IFERROR('Raw Data'!D26/'Raw Data'!C26-1,"") -> 0.031228632 | E7: =IFERROR('Raw Data'!E26/'Raw Data'!D26-1,"") -> -0.024540509 | F7: =IFERROR('Raw Data'!F26/'Raw Data'!E26-1,"") -> -0.028140942
A8: Total Equity | C8: =IFERROR('Raw Data'!C30/'Raw Data'!B30-1,"") -> 0.20643735 | D8: =IFERROR('Raw Data'!D30/'Raw Data'!C30-1,"") -> -0.084441414 | E8: =IFERROR('Raw Data'!E30/'Raw Data'!D30-1,"") -> 0.099847939 | F8: =IFERROR('Raw Data'!F30/'Raw Data'!E30-1,"") -> -0.03871168
A9: Inventory | C9: =IFERROR('Raw Data'!C14/'Raw Data'!B14-1,"") -> 0.39050543 | D9: =IFERROR('Raw Data'!D14/'Raw Data'!C14-1,"") -> -0.16243276 | E9: =IFERROR('Raw Data'!E14/'Raw Data'!D14-1,"") -> -0.050265434 | F9: =IFERROR('Raw Data'!F14/'Raw Data'!E14-1,"") -> -0.055036548
A10: Cash From Operating Activities | C10: =IFERROR('Raw Data'!C32/'Raw Data'!B32-1,"") -> -0.76829867 | D10: =IFERROR('Raw Data'!D32/'Raw Data'!C32-1,"") -> 1.3916961 | E10: =IFERROR('Raw Data'!E32/'Raw Data'!D32-1,"") -> 0.52456231 | F10: =IFERROR('Raw Data'!F32/'Raw Data'!E32-1,"") -> -0.53866654
A11: Gross PPE | C11: =IFERROR('Raw Data'!C37/'Raw Data'!B37-1,"") -> 0.14394508 | D11: =IFERROR('Raw Data'!D37/'Raw Data'!C37-1,"") -> 0.049657135 | E11: =IFERROR('Raw Data'!E37/'Raw Data'!D37-1,"") -> 0.034506856 | F11: =IFERROR('Raw Data'!F37/'Raw Data'!E37-1,"") -> 0.036150004
A12: Net PPE | C12: =IFERROR('Raw Data'!C39/'Raw Data'!B39-1,"") -> 0.16190498 | D12: =IFERROR('Raw Data'!D39/'Raw Data'!C39-1,"") -> 0.045133257 | E12: =IFERROR('Raw Data'!E39/'Raw Data'!D39-1,"") -> 0.033508957 | F12: =IFERROR('Raw Data'!F39/'Raw Data'!E39-1,"") -> 0.023802462

Sheet Common Size IS
A1: CT Item | B1: 2021 | C1: 2022 | D1: 2023 | E1: 2024 | F1: 2025
A2: Revenue | B2: ='Raw Data'!B3/'Raw Data'!B3 -> 1 | C2: ='Raw Data'!C3/'Raw Data'!C3 -> 1 | D2: ='Raw Data'!D3/'Raw Data'!D3 -> 1 | E2: ='Raw Data'!E3/'Raw Data'!E3 -> 1 | F2: ='Raw Data'!F3/'Raw Data'!F3 -> 1
A3: Cost of Sales | B3: ='Raw Data'!B4/'Raw Data'!B3 -> 0.6011748 | C3: ='Raw Data'!C4/'Raw Data'!C3 -> 0.65762523 | D3: ='Raw Data'!D4/'Raw Data'!D3 -> 0.65757512 | E3: ='Raw Data'!E4/'Raw Data'!E3 -> 0.65651249 | F3: ='Raw Data'!F4/'Raw Data'!F3 -> 0.65583035
A4: Gross Profit | B4: ='Raw Data'!B5/'Raw Data'!B3 -> 0.31159887 | C4: ='Raw Data'!C5/'Raw Data'!C3 -> 0.34237477 | D4: ='Raw Data'!D5/'Raw Data'!D3 -> 0.34242488 | E4: ='Raw Data'!E5/'Raw Data'!E3 -> 0.34348751 | F4: ='Raw Data'!F5/'Raw Data'!F3 -> 0.34416965
A5: Operating Income | B5: ='Raw Data'!B6/'Raw Data'!B3 -> 0.08774805 | C5: ='Raw Data'!C6/'Raw Data'!C3 -> 0.10189438 | D5: ='Raw Data'!D6/'Raw Data'!D3 -> 0.054837451 | E5: ='Raw Data'!E6/'Raw Data'!E3 -> 0.10846202 | F5: ='Raw Data'!F6/'Raw Data'!F3 -> 0.1026386
A6: Interest Expense (or Net Finance Costs) | B6: ='Raw Data'!B7/'Raw Data'!B3 -> 0.015743827 | C6: ='Raw Data'!C7/'Raw Data'!C3 -> 0.012969804 | D6: ='Raw Data'!D7/'Raw Data'!D3 -> 0.019301774 | E6: ='Raw Data'!E7/'Raw Data'!E3 -> 0.021335387 | F6: ='Raw Data'!F7/'Raw Data'!F3 -> 0.018111612
A7: Income Before Tax | B7: ='Raw Data'!B8/'Raw Data'!B3 -> 0.071942843 | C7: ='Raw Data'!C8/'Raw Data'!C3 -> 0.088924573 | D7: ='Raw Data'!D8/'Raw Data'!D3 -> 0.034388977 | E7: ='Raw Data'!E8/'Raw Data'!E3 -> 0.076171612 | F7: ='Raw Data'!F8/'Raw Data'!F3 -> 0.053844504
A8: Income Tax Expense | B8: ='Raw Data'!B9/'Raw Data'!B3 -> 0.018996937 | C8: ='Raw Data'!C9/'Raw Data'!C3 -> 0.022514682 | D8: ='Raw Data'!D9/'Raw Data'!D3 -> 0.014030559 | E8: ='Raw Data'!E9/'Raw Data'!E3 -> 0.016756532 | F8: ='Raw Data'!F9/'Raw Data'!F3 -> 0.013453464
A9: Net Income | B9: ='Raw Data'!B10/'Raw Data'!B3 -> 0.077381062 | C9: ='Raw Data'!C10/'Raw Data'!C3 -> 0.066409891 | D9: ='Raw Data'!D10/'Raw Data'!D3 -> 0.020358419 | E9: ='Raw Data'!E10/'Raw Data'!E3 -> 0.05941508 | F9: ='Raw Data'!F10/'Raw Data'!F3 -> 0.037369373

Sheet PPE Analysis
A1: Item | B1: 2021 | C1: 2022 | D1: 2023 | E1: 2024 | F1: 2025
A2: Gross PPE | B2: ='Raw Data'!B37 -> 7865.5 | C2: ='Raw Data'!C37 -> 8997.7 | D2: ='Raw Data'!D37 -> 9444.5 | E2: ='Raw Data'!E37 -> 9770.4 | F2: ='Raw Data'!F37 -> 10123.6
A3: Accumulated Depreciation | B3: ='Raw Data'!B38 -> 3567.3 | C3: ='Raw Data'!C38 -> 4003.6 | D3: ='Raw Data'!D38 -> 4225 | E3: ='Raw Data'!E38 -> 4376 | F3: ='Raw Data'!F38 -> 4600.8
A4: Net PPE | B4: ='Raw Data'!B39 -> 4298.2 | C4: ='Raw Data'!C39 -> 4994.1 | D4: ='Raw Data'!D39 -> 5219.5 | E4: ='Raw Data'!E39 -> 5394.4 | F4: ='Raw Data'!F39 -> 5522.8
A5: Net PPE / Total Assets | B5: ='Raw Data'!B39/'Raw Data'!B19 -> 0.21093286 | C5: ='Raw Data'!C39/'Raw Data'!C19 -> 0.22595386 | D5: ='Raw Data'!D39/'Raw Data'!D19 -> 0.23748425 | E5: ='Raw Data'!E39/'Raw Data'!E19 -> 0.24254741 | F5: ='Raw Data'!F39/'Raw Data'!F19 -> 0.25639978
A6: Accumulated Depreciation / Gross PPE | B6: ='Raw Data'!B38/'Raw Data'!B37 -> 0.4535376 | C6: ='Raw Data'!C38/'Raw Data'!C37 -> 0.44495816 | D6: ='Raw Data'!D38/'Raw Data'!D37 -> 0.44735031 | E6: ='Raw Data'!E38/'Raw Data'!E37 -> 0.4478834 | F6: ='Raw Data'!F38/'Raw Data'!F37 -> 0.45446284
A7: CapEx / Revenue | B7: ='Raw Data'!B33/'Raw Data'!B3 -> 0.026792126 | C7: ='Raw Data'!C33/'Raw Data'!C3 -> 0.046859735 | D7: ='Raw Data'!D33/'Raw Data'!D3 -> 0.034875274 | E7: ='Raw Data'!E33/'Raw Data'!E3 -> 0.035230899 | F7: ='Raw Data'!F33/'Raw Data'!F3 -> 0.035671601
A8: Depreciation / Gross PPE | B8: ='Raw Data'!B34/'Raw Data'!B37 -> 0.074070307 | C8: ='Raw Data'!C34/'Raw Data'!C37 -> 0.069017638 | D8: ='Raw Data'!D34/'Raw Data'!D37 -> 0.071491344 | E8: ='Raw Data'!E34/'Raw Data'!E37 -> 0.068052485 | F8: ='Raw Data'!F34/'Raw Data'!F37 -> 0.064591647

Sheet Dashboard
A1: Canadian Tire 2021–2025 Financial Analysis Summary
A3: Metric | B3: 2021 | C3: 2022 | D3: 2023 | E3: 2024 | F3: 2025
A4: Revenue | B4: ='Raw Data'!B3 -> 16292.1 | C4: ='Raw Data'!C3 -> 17810.6 | D4: ='Raw Data'!D3 -> 16656.5 | E4: ='Raw Data'!E3 -> 16357.8 | F4: ='Raw Data'!F3 -> 16315.5
A5: Net Income | B5: ='Raw Data'!B10 -> 1260.7 | C5: ='Raw Data'!C10 -> 1182.8 | D5: ='Raw Data'!D10 -> 339.1 | E5: ='Raw Data'!E10 -> 971.9 | F5: ='Raw Data'!F10 -> 609.7
A6: Cash From Operating Activities | B6: ='Raw Data'!B32 -> 2442.8 | C6: ='Raw Data'!C32 -> 566 | D6: ='Raw Data'!D32 -> 1353.7 | E6: ='Raw Data'!E32 -> 2063.8 | F6: ='Raw Data'!F32 -> 952.1
A7: Total Assets | B7: ='Raw Data'!B19 -> 20377.1 | C7: ='Raw Data'!C19 -> 22102.3 | D7: ='Raw Data'!D19 -> 21978.3 | E7: ='Raw Data'!E19 -> 22240.6 | F7: ='Raw Data'!F19 -> 21539.8
A8: Total Liabilities | B8: ='Raw Data'!B26 -> 14542.4 | C8: ='Raw Data'!C26 -> 15063.1 | D8: ='Raw Data'!D26 -> 15533.5 | E8: ='Raw Data'!E26 -> 15152.3 | F8: ='Raw Data'!F26 -> 14725.9
A9: Gross Margin | B9: =Ratios!B3 -> 0.31159887 | C9: =Ratios!C3 -> 0.34237477 | D9: =Ratios!D3 -> 0.34242488 | E9: =Ratios!E3 -> 0.34348751 | F9: =Ratios!F3 -> 0.34416965
A10: Net Margin | B10: =Ratios!B5 -> 0.077381062 | C10: =Ratios!C5 -> 0.066409891 | D10: =Ratios!D5 -> 0.020358419 | E10: =Ratios!E5 -> 0.05941508 | F10: =Ratios!F5 -> 0.037369373
A11: Current Ratio | B11: =Ratios!B6 -> 2.025971 | C11: =Ratios!C6 -> 1.6133203 | D11: =Ratios!D6 -> 1.7675849 | E11: =Ratios!E6 -> 1.7911892 | F11: =Ratios!F6 -> 1.8262406
A12: Debt Ratio | B12: =Ratios!B8 -> 0.71366387 | C12: =Ratios!C8 -> 0.68151731 | D12: =Ratios!D8 -> 0.70676531 | E12: =Ratios!E8 -> 0.68129007 | F12: =Ratios!F8 -> 0.68366002

Sheet Empire Balance Sheet
A1: Balance Sheet as of: | D1: May-01-2021 | F1: May-07-2022 | H1: May-06-2023 | J1: Restated May-04-2024 | L1: May-03-2025 | N1: May-02-2026
B2: Currency | D2: CAD | F2: CAD | H2: CAD | J2: CAD | L2: CAD | N2: CAD
B3: ASSETS
D4: 890.5 | F4: 812.3 | H4: 221.3 | J4: 260 | L4: 285 | N4: 291
B5: Cash And Equivalents
B7: Total Cash & ST Investments | D7: 890.5 | F7: 812.3 | H7: 221.3 | J7: 260 | L7: 285 | N7: 291
D9: 638 | F9: 632.6 | H9: 768.6 | J9: 793 | L9: 789 | N9: 838
B10: Accounts Receivable
D11: 60.5 | F11: 48.7 | H11: 90.8 | J11: 70 | L11: 54 | N11: 138
B12: Other Receivables
B14: Total Receivables | D14: 698.5 | F14: 681.3 | H14: 859.4 | J14: 863 | L14: 843 | N14: 976
D16: 1500.1 | F16: 1591.5 | H16: 1743.3 | J16: 1772 | L16: 1833 | N16: 1919
B17: Inventory
D18: 101 | F18: 127.6 | H18: 131 | J18: 162 | L18: 173 | N18: 204
B19: Prepaid Exp.
D20: 3.4 | F20: - | H20: - | J20: 47 | L20: - | N20: -
B21: Other Current Assets
B23: Total Current Assets | D23: 3193.5 | F23: 3212.7 | H23: 2955 | J23: 3104 | L23: 3134 | N23: 3390
D25: 10195 | F25: 10807.2 | H25: 10974.8 | J25: 11388 | L25: 11756 | N25: 11809
B26: Gross Property, Plant & Equipment
D27: -2538.5 | F27: -2648.3 | H27: -2775.8 | J27: -2905 | L27: -3117 | N27: -3388
B28: Accumulated Depreciation
B30: Net Property, Plant & Equipment | D30: 7656.5 | F30: 8158.9 | H30: 8199 | J30: 8483 | L30: 8639 | N30: 8421
D32: 577.7 | F32: 681.5 | H32: 701.9 | J32: 688 | L32: 720 | N32: 721
B33: Long-term Investments
D34: 1577.8 | F34: 2059 | H34: 2067.8 | J34: 2064 | L34: 2055 | N34: 2056
B35: Goodwill
D36: 976 | F36: 1338.5 | H36: 1375.6 | J36: 1348 | L36: 1359 | N36: 1327
B37: Other Intangibles
D38: 497.1 | F38: 503.6 | H38: 541.4 | J38: 536 | L38: 559 | N38: 513
B39: Accounts Receivable Long-Term
D40: 47.1 | F40: 45.5 | H40: 45.6 | J40: 65 | L40: 77 | N40: 69
B41: Loans Receivable Long-Term
D42: 474.9 | F42: 425.4 | H42: 404.3 | J42: 305 | L42: 270 | N42: 423
B43: Deferred Tax Assets, LT
D44: 173.3 | F44: 168.5 | H44: 193.1 | J44: 197 | L44: 206 | N44: 160
B45: Other Long-Term Assets
B47: Total Assets | D47: 15173.9 | F47: 16593.6 | H47: 16483.7 | J47: 16790 | L47: 17019 | N47: 17080
B49: LIABILITIES
D50: 2874.1 | F50: 2988.9 | H50: 3028.6 | J50: 2874 | L50: 2960 | N50: 2836
...

Sheet Empire Income Statement
E1: Reclassified 12 months May-01-2021 | F1: Reclassified 12 months May-07-2022 | G1: Reclassified 12 months May-06-2023 | H1: Restated 12 months May-04-2024 | I1: Reclassified 12 months May-03-2025 | J1: 12 months May-02-2026
C2: Currency | E2: CAD | F2: CAD | G2: CAD | H2: CAD | I2: CAD | J2: CAD
E3: 28268.3 | F3: 30162.4 | G3: 30478.1 | H3: 30733 | I3: 31277 | J3: 31950
C4: Revenue
C5: Other Revenue | E5: 67.3 | F5: 109.8 | G5: 103.8 | H5: 67 | I5: 83 | J5: 79
C7: Total Revenue | E7: 28335.6 | F7: 30272.2 | G7: 30581.9 | H7: 30800 | I7: 31360 | J7: 32029
C8: Cost Of Goods Sold | E8: 21069 | F8: 22502.7 | G8: 22685.4 | H8: 22662 | I8: 22895 | J8: 23286
C9: Gross Profit | E9: 7266.6 | F9: 7769.5 | G9: 7896.5 | H9: 8138 | I9: 8465 | J9: 8743
C10: Selling General & Admin Exp. | E10: 6010.7 | F10: 6491.1 | G10: 6703.7 | H10: 6998 | I10: 7246 | J10: 7467
C11: R & D Exp. | E11: - | F11: - | G11: - | H11: - | I11: - | J11: -
C12: Depreciation & Amort. | E12: - | F12: - | G12: - | H12: - | I12: - | J12: -
C13: Other Operating Expense/(Income) | E13: - | F13: -47 | G13: - | H13: - | I13: - | J13: -
C14: Other Operating Exp., Total | E14: 6010.7 | F14: 6444.1 | G14: 6703.7 | H14: 6998 | I14: 7246 | J14: 7467
C15: Operating Income | E15: 1255.9 | F15: 1325.4 | G15: 1192.8 | H15: 1140 | I15: 1219 | J15: 1276
C16: Interest Expense | E16: -292.8 | F16: -301.9 | G16: -284 | H16: -304 | I16: -319 | J16: -315
C17: Interest and Invest. Income | E17: 29.5 | F17: 26.1 | G17: 23.8 | H17: 27 | I17: 26 | J17: 33
C19: Net Interest Exp. | E19: -263.3 | F19: -275.8 | G19: -260.2 | H19: -277 | I19: -293 | J19: -282
C21: Other Non-Operating Inc. (Exp.) | E21: 2 | F21: 1.5 | G21: 1 | H21: 19 | I21: 6 | J21: 11
C22: EBT Excl. Unusual Items | E22: 994.6 | F22: 1051.1 | G22: 933.6 | H22: 882 | I22: 932 | J22: 1005
C24: Impairment of Goodwill | E24: - | F24: - | G24: - | H24: - | I24: - | J24: -
C25: Gain (Loss) On Sale Of Assets | E25: 37.1 | F25: 23.1 | G25: 44.7 | H25: 108 | I25: 57 | J25: 38
C26: Asset Writedown | E26: -1.6 | F26: 7.4 | G26: -12.9 | H26: - | I26: -12 | J26: -747
C27: Other Unusual Items | E27: - | F27: - | G27: - | H27: 39 | I27: 18 | J27: 12
C28: EBT Incl. Unusual Items | E28: 1030.1 | F28: 1081.6 | G28: 965.4 | H28: 1029 | I28: 995 | J28: 308
C30: Income Tax Expense | E30: 265.9 | F30: 270.3 | G30: 237.7 | H30: 266 | I30: 249 | J30: 62
C31: Earnings from Cont. Ops. | E31: 764.2 | F31: 811.3 | G31: 727.7 | H31: 763 | I31: 746 | J31: 246
C33: Earnings of Discontinued Ops. | E33: - | F33: - | G33: - | H33: - | I33: - | J33: -
C34: Extraord. Item & Account. Change | E34: - | F34: - | G34: - | H34: - | I34: - | J34: -
C35: Net Income to Company | E35: 764.2 | F35: 811.3 | G35: 727.7 | H35: 763 | I35: 746 | J35: 246
E37: -62.7 | F37: -65.5 | G37: -41.7 | H37: -37 | I37: -46 | J37: -48
C38: Minority Int. in Earnings
L39: 2021 | M39: 2022 | N39: 2023 | O39: 2024 | P39: 2025 | Q39: 2026
C40: Net Income | E40: 701.5 | F40: 745.8 | G40: 686 | H40: 726 | I40: 700 | J40: 198 | L40: =E40/E7 -> 0.024756843 | M40: =F40/F7 -> 0.024636465 | N40: =G40/G7 -> 0.022431569 | O40: =H40/H7 -> 0.023571429 | P40: =I40/I7 -> 0.022321429 | Q40: =J40/J7 -> 0.0061818977
E42: - | F42: - | G42: - | H42: - | I42: - | J42: -
C43: Pref. Dividends and Other Adj.
E45: 701.5 | F45: 745.8 | G45: 686 | H45: 726 | I45: 700 | J45: 198
C46: NI to Common Incl Extra Items
E47: 701.5 | F47: 745.8 | G47: 686 | H47: 726 | I47: 700 | J47: 198
C48: NI to Common Excl. Extra Items
C50: Per Share Items
...

Sheet Charts
A1: Year | B1: 2021 | C1: 2022 | D1: 2023 | E1: 2024 | F1: 2025 | G1: 2026
A2: Canadian Tire Net Income | B2: 1260.7 | C2: 1182.8 | D2: 339.1 | E2: 971.9 | F2: 609.7
A3: Empire Net Income | B3: 701.5 | C3: 745.8 | D3: 686 | E3: 726 | F3: 700 | G3: 198
A4: Canadian Tire Net Margin | B4: 0.077381062 | C4: 0.066409891 | D4: 0.020358419 | E4: 0.05941508 | F4: 0.037369373
A5: Empire Net Margin | B5: 0.024756843 | C5: 0.024636465 | D5: 0.022431569 | E5: 0.023571429 | F5: 0.022321429 | G5: 0.0061818977

Sheet Industry Data
A1: Company | B1: Period | C1: Period End Date | D1: Total Assets | E1: Total Liabilities | F1: Total Equity | G1: Inventory | H1: Current Assets | I1: Current Liabilities | J1: Cash & Equivalents | K1: Total Debt | L1: Long-Term Debt | M1: Short-Term Debt | N1: CFO | O1: CapEx | P1: Free Cash Flow | Q1: Dividends Paid | R1: Share Repurchases | S1: Interest Expense | T1: Income Before Tax | U1: Revenue | V1: Gross Profit | W1: EBITDA | X1: EBIT | Y1: Net Income | Z1: Revenue Growth | AA1: Gross Margin | AB1: EBITDA Margin | AC1: EBIT Margin | AD1: Net Margin | AE1: ROA | AF1: ROE | AG1: Current Ratio | AH1: Quick Ratio | AI1: Debt/Equity | AJ1: Debt/Capital | AK1: Debt/EBITDA | AL1: Asset Turnover | AM1: Inventory Turnover
A2: Metro Inc. | B2: 2021 | C2: 25/09/2021 | D2: 13592.1 | E2: 7179.3 | F2: 6412.8 | G2: 1169 | H2: 2466.8 | I2: 2198.2 | J2: 445.8 | K2: 4564 | L2: 2318.2 | M2: 588.3 | N2: 1583.3 | O2: -469.2 | P2: 697.2 | Q2: -240.1 | R2: -456.3 | S2: -143.2 | T2: 1120.7 | U2: 18283 | V2: 3654.8 | W2: 1542.8 | X2: 1242.5 | Y2: 823 | Z2: 0.016 | AA2: 0.2 | AB2: 0.084 | AC2: 0.068 | AD2: 0.045 | AE2: 0.057 | AF2: 0.131 | AG2: 1.1 | AH2: 0.6 | AI2: 0.712 | AJ2: 0.416 | AK2: 2.7 | AL2: 1.4 | AM2: 12
A3: Metro Inc. | B3: 2022 | C3: 24/09/2022 | D3: 13401.3 | E3: 6782.9 | F3: 6618.4 | G3: 1331.1 | H3: 2183.3 | I3: 1952.5 | J3: 13.4 | K3: 4137.2 | L3: 2339.9 | M3: 294.6 | N3: 1461.4 | O3: -497.3 | P3: 559.6 | Q3: -257.9 | R3: -470 | S3: -134.2 | T3: 1153.6 | U3: 18888.9 | V3: 3783.3 | W3: 1634.9 | X3: 1315.7 | Y3: 846.1 | Z3: 0.033 | AA3: 0.2 | AB3: 0.087 | AC3: 0.07 | AD3: 0.045 | AE3: 0.061 | AF3: 0.13 | AG3: 1.1 | AH3: 0.4 | AI3: 0.625 | AJ3: 0.385 | AK3: 2.3 | AL3: 1.4 | AM3: 12.1
A4: Metro Inc. | B4: 2023 | C4: 30/09/2023 | D4: 13865.3 | E4: 7049 | F4: 6816.3 | G4: 1451 | H4: 2403.6 | I4: 1960.8 | J4: 29.5 | K4: 4337.1 | L4: 2659.1 | M4: 297.7 | N4: 1563.5 | O4: -580.7 | P4: 485.5 | Q4: -275 | R4: -593.6 | S4: -151.4 | T4: 1321.8 | U4: 20724.6 | V4: 4082.2 | W4: 1780.7 | X4: 1443.4 | Y4: 1014.8 | Z4: 0.097 | AA4: 0.197 | AB4: 0.086 | AC4: 0.07 | AD4: 0.049 | AE4: 0.066 | AF4: 0.152 | AG4: 1.2 | AH4: 0.5 | AI4: 0.636 | AJ4: 0.389 | AK4: 2.2 | AL4: 1.5 | AM4: 12
A5: Metro Inc. | B5: 2024 | C5: 28/09/2024 | D5: 14140.6 | E5: 7101.7 | F5: 7038.9 | G5: 1508.3 | H5: 2474 | I5: 2285.6 | J5: 29.4 | K5: 4311.8 | L5: 2358.4 | M5: 580.8 | N5: 1677 | O5: -482.4 | P5: 778 | Q5: -294.6 | R5: -485.7 | S5: -167.9 | T5: 1250.1 | U5: 21219.9 | V5: 4179.3 | W5: 1790.2 | X5: 1416 | Y5: 928.8 | Z5: 0.024 | AA5: 0.197 | AB5: 0.084 | AC5: 0.067 | AD5: 0.044 | AE5: 0.063 | AF5: 0.134 | AG5: 1.1 | AH5: 0.4 | AI5: 0.613 | AJ5: 0.38 | AK5: 2.2 | AL5: 1.5 | AM5: 11.5
A6: Metro Inc. | B6: 2025 | C6: 27/09/2025 | D6: 14539.4 | E6: 7494.3 | F6: 7045.1 | G6: 1604.3 | H6: 2661 | I6: 2053.8 | J6: 67.3 | K6: 4602 | L6: 2938.1 | M6: 293.1 | N6: 1724.9 | O6: -438.2 | P6: 840.6 | Q6: -316.8 | R6: -801.3 | S6: -165.6 | T6: 1320.2 | U6: 22006.7 | V6: 4345.8 | W6: 1861.6 | X6: 1471.3 | Y6: 1017 | Z6: 0.037 | AA6: 0.197 | AB6: 0.085 | AC6: 0.067 | AD6: 0.046 | AE6: 0.064 | AF6: 0.145 | AG6: 1.3 | AH6: 0.5 | AI6: 0.653 | AJ6: 0.395 | AK6: 2.3 | AL6: 1.5 | AM6: 11.3
A7: Average over 5 years | U7: =AVERAGE(U2:U6) -> 20224.62 | V7: =AVERAGE(V2:V6) -> 4009.08 | W7: =AVERAGE(W2:W6) -> 1722.04 | X7: =AVERAGE(X2:X6) -> 1377.78 | Y7: =AVERAGE(Y2:Y6) -> 925.94 | Z7: =AVERAGE(Z2:Z6) -> 0.0414 | AA7: =AVERAGE(AA2:AA6) -> 0.1982 | AB7: =AVERAGE(AB2:AB6) -> 0.0852 | ... AM7: =AVERAGE(AM2:AM6) -> 11.78
A8: Loblaw Companies Limited | B8: 2021 | C8: 44562 | D8: 36614 | E8: 24877 | F8: 11737 | G8: 5166 | H8: 12637 | I8: 9196 | J8: 2441 | K8: 16554 | L8: 4297 | M8: 52 | N8: 4827 | O8: -803 | P8: 3661 | Q8: -484 | R8: -1250 | S8: -431 | T8: 2442 | U8: 53170 | V8: 16670 | W8: 4266 | X8: 2927 | Y8: 1875 | Z8: 0.009 | AA8: 0.314 | AB8: 0.08 | AC8: 0.055 | AD8: 0.035 | AE8: 0.05 | AF8: 0.173 | AG8: 1.4 | AH8: 0.8 | AI8: 1.41 | AJ8: 0.585 | AK8: 3.2 | AL8: 1.5 | AM8: 7
A9: Loblaw Companies Limited | B9: 2022 | C9: 31/12/2022 | D9: 38147 | E9: 26691 | F9: 11456 | G9: 5855 | H9: 13376 | I9: 10098 | J9: 1935 | K9: 17606 | L9: 4866 | M9: 8 | N9: 4755 | O9: -1152 | P9: 3153.1 | Q9: -529 | R9: -1396 | S9: -599 | T9: 2659 | U9: 56504 | V9: 17892 | W9: 4698 | X9: 3308 | Y9: 1921 | Z9: 0.063 | AA9: 0.317 | AB9: 0.083 | AC9: 0.059 | AD9: 0.034 | AE9: 0.055 | AF9: 0.172 | AG9: 1.3 | AH9: 0.7 | AI9: 1.537 | AJ9: 0.606 | AK9: 3.1 | AL9: 1.5 | AM9: 7
A10: Loblaw Companies Limited | B10: 2023 | C10: 30/12/2023 | D10: 38979 | E10: 27360 | F10: 11619 | G10: 5820 | H10: 13578 | I10: 10847 | J10: 1953 | K10: 18173 | L10: 4460 | M10: 13 | N10: 5654 | O10: -1665 | P10: 2835.8 | Q10: -562 | R10: -1801 | S10: -660 | T10: 2901 | U10: 59529 | V10: 18894 | W10: 5014 | X10: 3578 | Y10: 2100 | Z10: 0.054 | AA10: 0.317 | AB10: 0.084 | AC10: 0.06 | AD10: 0.035 | AE10: 0.058 | AF10: 0.19 | AG10: 1.3 | AH10: 0.7 | AI10: 1.564 | AJ10: 0.61 | AK10: 3 | AL10: 1.5 | AM10: 6.9
A11: Loblaw Companies Limited | B11: 2024 | C11: 28/12/2024 | D11: 40880 | E11: 29614 | F11: 11266 | G11: 6330 | H11: 14548 | I11: 11768 | J11: 2110 | K11: 19184 | L11: 7570 | N11: 5802 | O11: -1823 | P11: 3006.4 | Q11: -459 | R11: -1826 | S11: -706 | T11: 2791 | U11: 60123 | V11: 18835 | W11: 5119 | X11: 3665 | Y11: 2171 | Z11: 0.01 | AA11: 0.313 | AB11: 0.085 | AC11: 0.061 | AD11: 0.036 | AE11: 0.057 | AF11: 0.18 | AG11: 1.2 | AH11: 0.7 | AI11: 1.703 | AJ11: 0.63 | AK11: 3.1 | AL11: 1.5 | AM11: 6.8
A12: Loblaw Companies Limited | B12: 2025 | C12: 46082 | D12: 41577 | E12: 30385 | F12: 11192 | G12: 6491 | H12: 14928 | I12: 13870 | J12: 1041 | K12: 16305 | L12: 5891 | N12: 6264 | O12: -1712 | P12: 3774.3 | Q12: -812 | R12: -1981 | S12: -763 | T12: 3682 | U12: 63903 | V12: 20032 | W12: 5635 | X12: 4469 | Y12: 2667 | Z12: 0.063 | AA12: 0.313 | AB12: 0.088 | AC12: 0.07 | AD12: 0.042 | AE12: 0.068 | AF12: 0.232 | AG12: 1.1 | AH12: 0.2 | AI12: 1.457 | AJ12: 0.593 | AK12: 2.4 | AL12: 1.5 | AM12: 6.8
A13: Average over 5 years | U13: =AVERAGE(U8:U12) -> 58645.8 | V13: =AVERAGE(V8:V12) -> 18464.6 | W13: =AVERAGE(W8:W12) -> 4946.4 | X13: =AVERAGE(X8:X12) -> 3589.4 | Y13: =AVERAGE(Y8:Y12) -> 2146.8 | Z13: =AVERAGE(Z8:Z12) -> 0.0398 | AA13: =AVERAGE(AA8:AA12) -> 0.3148 | AB13: =AVERAGE(AB8:AB12) -> 0.084 | ... AM13: =AVERAGE(AM8:AM12) -> 6.9
A14: Empire Company Limited | B14: 2021 | C14: 44201 | D14: 15173.9 | E14: 10675.9 | F14: 4498 | G14: 1500.1 | H14: 3193.5 | I14: 3488.2 | J14: 890.5 | K14: 7133.4 | L14: 1178.8 | M14: 46.5 | N14: 1859.6 | O14: -566.3 | P14: 707.3 | Q14: -139.4 | R14: -153.6 | S14: -292.8 | T14: 1030.1 | U14: 28335.6 | V14: 7266.6 | W14: 1652.4 | X14: 1255.9 | Y14: 701.5 | Z14: 0.062 | AA14: 0.256 | AB14: 0.058 | AC14: 0.044 | AD14: 0.025 | AE14: 0.053 | AF14: 0.18 | AG14: 0.9 | AH14: 0.5 | AI14: 1.586 | AJ14: 0.613 | AK14: 3.5 | AL14: 1.9 | AM14: 14.1
A15: Empire Company Limited | B15: 2022 | C15: 44747 | D15: 16593.6 | E15: 11459.7 | F15: 5133.9 | G15: 1591.5 | H15: 3212.7 | I15: 4239.7 | J15: 812.3 | K15: 7462.1 | L15: 595.7 | M15: 581 | N15: 2107.1 | O15: -633 | P15: 962.4 | Q15: -156.8 | R15: -248.9 | S15: -301.9 | T15: 1081.6 | U15: 30272.2 | V15: 7769.5 | W15: 1768 | X15: 1325.4 | Y15: 745.8 | Z15: 0.068 | AA15: 0.257 | AB15: 0.058 | AC15: 0.044 | AD15: 0.025 | AE15: 0.052 | AF15: 0.168 | AG15: 0.8 | AH15: 0.4 | AI15: 1.453 | AJ15: 0.592 | AK15: 3.3 | AL15: 1.9 | AM15: 14.6
A16: Empire Company Limited | B16: 2023 | C16: 45082 | D16: 16483.7 | E16: 11147 | F16: 5336.7 | G16: 1743.3 | H16: 2955 | I16: 3857.5 | J16: 221.3 | K16: 7196.9 | L16: 911.3 | M16: 101 | N16: 1605.3 | O16: -574.2 | P16: 564.2 | Q16: -170.2 | R16: -350 | S16: -284 | T16: 965.4 | U16: 30581.9 | V16: 7896.5 | W16: 1660.9 | X16: 1192.8 | Y16: 686 | Z16: 0.01 | AA16: 0.258 | AB16: 0.054 | AC16: 0.039 | AD16: 0.022 | AE16: 0.045 | AF16: 0.139 | AG16: 0.8 | AH16: 0.3 | AI16: 1.349 | AJ16: 0.574 | AK16: 3.4 | AL16: 1.8 | AM16: 13.6
A17: Empire Company Limited | B17: 2024 | C17: 45387 | D17: 16790 | E17: 11321 | F17: 5469 | G17: 1772 | H17: 3104 | I17: 3891 | J17: 260 | K17: 7361 | L17: 982 | M17: 114 | N17: 2073 | O17: -705 | P17: 699.4 | Q17: -179 | R17: -400 | S17: -304 | T17: 1029 | U17: 30800 | V17: 8138 | W17: 2123 | X17: 1140 | Y17: 726 | Z17: 0.007 | AA17: 0.264 | AB17: 0.069 | AC17: 0.037 | AD17: 0.024 | AE17: 0.043 | AF17: 0.141 | AG17: 0.8 | AH17: 0.3 | AI17: 1.346 | AJ17: 0.574 | AK17: 3.5 | AL17: 1.9 | AM17: 12.9
A18: Empire Company Limited | B18: 2025 | C18: 45721 | D18: 17019 | E18: 11475 | F18: 5544 | G18: 1833 | H18: 3134 | I18: 4096 | J18: 285 | K18: 7464 | L18: 857 | M18: 225 | N18: 2127 | O18: -640 | P18: 1095.1 | Q18: -190 | R18: -400 | S18: -319 | T18: 995 | U18: 31360 | V18: 8465 | W18: 2291 | X18: 1260 | Y18: 700 | Z18: 0.018 | AA18: 0.27 | AB18: 0.073 | AC18: 0.04 | AD18: 0.022 | AE18: 0.047 | AF18: 0.135 | AG18: 0.8 | AH18: 0.3 | AI18: 1.346 | AJ18: 0.574 | AK18: 3.3 | AL18: 1.9 | AM18: 12.7
U19: =AVERAGE(U14:U18) -> 30269.94 | V19: =AVERAGE(V14:V18) -> 7907.12 | W19: =AVERAGE(W14:W18) -> 1899.06 | X19: =AVERAGE(X14:X18) -> 1234.82 | Y19: =AVERAGE(Y14:Y18) -> 711.86 | Z19: =AVERAGE(Z14:Z18) -> 0.033 | AA19: =AVERAGE(AA14:AA18) -> 0.261 | AB19: =AVERAGE(AB14:AB18) -> 0.0624 | ... AM19: =AVERAGE(AM14:AM18) -> 13.58
A20: Dollarama Inc. (TSX:DOL) | B20: 2021 | C20: Jan-31-2021 | D20: 4223.7 | E20: 3888.9 | F20: 334.9 | G20: 630.7 | H20: 1100.4 | I20: 1321.2 | J20: 439.1 | K20: 3460.6 | L20: 1044.1 | M20: 1014.7 | N20: 888.6 | O20: -140 | P20: 645.3 | Q20: -54.8 | R20: -87 | S20: -95.6 | T20: 765.4 | U20: 4026.3 | V20: 1911.6 | W20: 999.3 | X20: 925.3 | Y20: 564.3 | Z20: 0.063 | AA20: 0.475 | AB20: 0.248 | AC20: 0.23 | AD20: 0.14 | AE20: 0.146 | AF20: 4.651 | AG20: 0.8 | AH20: 0.3 | AI20: 10.335 | AJ20: 0.912 | AK20: 2.9 | AL20: 1 | AM20: 3.4
A21: Dollarama Inc. (TSX:DOL) | B21: 2022 | C21: Jan-30-2022 | D21: 4063.6 | E21: 4129.6 | F21: -66 | G21: 590.9 | H21: 717.4 | I21: 911.9 | J21: 71.1 | K21: 3616.7 | L21: 1539.2 | M21: 550.9 | N21: 1159.2 | O21: -136.8 | P21: 776.4 | Q21: -60.5 | R21: -1059.9 | S21: -91.2 | T21: 893.4 | U21: 4330.8 | V21: 2049 | W21: 1070.6 | X21: 986.9 | Y21: 663.2 | Z21: 0.076 | AA21: 0.473 | AB21: 0.247 | AC21: 0.228 | AD21: 0.153 | AE21: 0.149 | AF21: 4.934 | AG21: 0.8 | AH21: 0.1 | AI21: NM | AJ21: 1.019 | AK21: 2.9 | AL21: 1 | AM21: 3.7
A22: Dollarama Inc. (TSX:DOL) | B22: 2023 | C22: Jan-29-2023 | D22: 4819.7 | E22: 4791.2 | F22: 28.4 | G22: 957.2 | H22: 1156.9 | I22: 1162.9 | J22: 101.3 | K22: 4218.8 | L22: 1741.6 | M22: 735.3 | N22: 869 | O22: -134 | P22: 483.4 | Q22: -63 | R22: -689 | S22: -126.8 | T22: 1076.1 | U22: 5052.7 | V22: 2351 | W22: 1239.1 | X22: 1146.1 | Y22: 801.9 | Z22: 0.167 | AA22: 0.465 | AB22: 0.245 | AC22: 0.227 | AD22: 0.159 | AE22: 0.161 | AF22: NM | AG22: 1 | AH22: 0.1 | AI22: 148.497 | AJ22: 0.993 | AK22: 2.9 | AL22: 1.1 | AM22: 3.5
A23: Dollarama Inc. (TSX:DOL) | B23: 2024 | C23: Jan-28-2024 | D23: 5263.6 | E23: 4882.8 | F23: 380.8 | G23: 916.8 | H23: 1309.1 | I23: 677.8 | J23: 315.9 | K23: 4333.6 | L23: 2242.9 | M23: 256 | N23: 1531 | O23: -252.7 | P23: 939.8 | Q23: -76.1 | R23: -655.9 | S23: -167.2 | T23: 1350.9 | U23: 5867.3 | V23: 2613.4 | W23: 1524.4 | X23: 1420.4 | Y23: 1010.5 | Z23: 0.161 | AA23: 0.445 | AB23: 0.26 | AC23: 0.242 | AD23: 0.172 | AE23: 0.176 | AF23: 4.938 | AG23: 1.9 | AH23: 0.6 | AI23: 11.379 | AJ23: 0.919 | AK23: 2.5 | AL23: 1.2 | AM23: 3.5
A24: Dollarama Inc. (TSX:DOL) | B24: 2025 | C24: Feb-02-2025 | D24: 6482.6 | E24: 5294.3 | F24: 1188.3 | G24: 921.1 | H24: 1201.3 | I24: 1014.3 | J24: 135 | K24: 4709.7 | L24: 2008.9 | M24: 552.5 | N24: 1644.1 | O24: -212.8 | P24: 1021 | Q24: -97.2 | R24: -1090.7 | S24: -187.5 | T24: 1546.9 | U24: 6413.1 | V24: 2893.7 | W24: 1697 | X24: 1580.8 | Y24: 1168.5 | Z24: 0.093 | AA24: 0.451 | AB24: 0.265 | AC24: 0.246 | AD24: 0.182 | AE24: 0.168 | AF24: 1.489 | AG24: 1.2 | AH24: 0.2 | AI24: 3.963 | AJ24: 0.799 | AK24: 2.4 | AL24: 1.1 | AM24: 3.8
U25: =AVERAGE(U20:U24) -> 5138.04 | V25: =AVERAGE(V20:V24) -> 2363.74 | W25: =AVERAGE(W20:W24) -> 1306.08 | X25: =AVERAGE(X20:X24) -> 1211.9 | Y25: =AVERAGE(Y20:Y24) -> 841.68 | Z25: =AVERAGE(Z20:Z24) -> 0.112 | AA25: =AVERAGE(AA20:AA24) -> 0.4618 | AB25: =AVERAGE(AB20:AB24) -> 0.253 | ... AM25: =AVERAGE(AM20:AM24) -> 3.58
A26: Canadian Tire Corporation, Limited (TSX:CTC.A) | B26: 2021 | C26: 44562 | D26: 21802.2 | E26: 15291.4 | F26: 6510.8 | G26: 2480.6 | H26: 11646.6 | I26: 6790 | J26: 2357.9 | K26: 10556.2 | L26: 1379.1 | M26: 58 | N26: 1735.9 | O26: -630.6 | P26: 1378.9 | Q26: -271.1 | R26: -131.1 | S26: -236.2 | T26: 1701.9 | U26: 16292.1 | V26: 5478.1 | W26: 2230.8 | X26: 1941.6 | Y26: 1127.6 | Z26: 0.096 | AA26: 0.336 | AB26: 0.137 | AC26: 0.119 | AD26: 0.069 | AE26: 0.058 | AF26: 0.204 | AG26: 1.7 | AH26: 1.3 | AI26: 1.621 | AJ26: 0.619 | AK26: 4.2 | AL26: 0.8 | AM26: 4.2
A27: Canadian Tire Corporation, Limited (TSX:CTC.A) | B27: 2022 | C27: 31/12/2022 | D27: 22102.3 | E27: 15063.1 | F27: 7039.2 | G27: 3216.1 | H27: 11530.4 | I27: 7147 | J27: 507.6 | K27: 10212.2 | L27: 1148.4 | M27: 126.6 | N27: 466.5 | O27: -612.5 | P27: -752.8 | Q27: -325.8 | R27: -425.4 | S27: -251.9 | T27: 1583.8 | U27: 17810.6 | V27: 5735.6 | W27: 2216.6 | X27: 1924.5 | Y27: 1044.1 | Z27: 0.093 | AA27: 0.322 | AB27: 0.124 | AC27: 0.108 | AD27: 0.059 | AE27: 0.055 | AF27: 0.175 | AG27: 1.6 | AH27: 1.1 | AI27: 1.451 | AJ27: 0.592 | AK27: 4 | AL27: 0.8 | AM27: 3.9
A28: Canadian Tire Corporation, Limited (TSX:CTC.A) | B28: 2023 | C28: 30/12/2023 | D28: 21978.3 | E28: 15533.5 | F28: 6444.8 | G28: 2693.7 | H28: 11293.1 | I28: 6389 | J28: 105.4 | K28: 11659 | L28: 2419.2 | M28: 525.6 | N28: 1353.7 | O28: -580.9 | P28: -60.9 | Q28: -360.8 | R28: -376.1 | S28: -361.3 | T28: 572.8 | U28: 16656.5 | V28: 5699.9 | W28: 1636.7 | X28: 1317.6 | Y28: 213.3 | Z28: -0.065 | AA28: 0.342 | AB28: 0.098 | AC28: 0.079 | AD28: 0.013 | AE28: 0.037 | AF28: 0.05 | AG28: 1.8 | AH28: 1.3 | AI28: 1.809 | AJ28: 0.644 | AK28: 5.9 | AL28: 0.8 | AM28: 3.5
A29: Canadian Tire Corporation, Limited (TSX:CTC.A) | B29: 2024 | C29: 28/12/2024 | D29: 22240.6 | E29: 15152.3 | F29: 7088.3 | G29: 2558.3 | H29: 11347.9 | I29: 6335.4 | J29: 176 | K29: 10899.2 | L29: 1900.6 | M29: 2 | N29: 2063.8 | O29: -567.8 | P29: 1029.2 | Q29: -359.8 | R29: -29.8 | S29: -384.6 | T29: 1175.1 | U29: 15516 | V29: 4820.9 | W29: 1546.5 | X29: 1247.1 | Y29: 887.7 | Z29: -0.068 | AA29: 0.311 | AB29: 0.1 | AC29: 0.08 | AD29: 0.057 | AE29: 0.035 | AF29: 0.135 | AG29: 1.8 | AH29: 1.3 | AI29: 1.538 | AJ29: 0.606 | AK29: 5.8 | AL29: 0.7 | AM29: 3.6
A30: Canadian Tire Corporation, Limited (TSX:CTC.A) | B30: 2025 | C30: 46082 | D30: 21539.8 | E30: 14725.9 | F30: 6813.9 | G30: 2417.5 | H30: 11316.3 | I30: 6196.5 | J30: 214.9 | K30: 10655 | L30: 1623.3 | N30: 952.1 | O30: -582 | P30: 780.6 | Q30: -361.7 | R30: -467.2 | S30: -329.7 | T30: 878.5 | U30: 16315.5 | V30: 5188.3 | W30: 1741 | X30: 1408.9 | Y30: 526.3 | Z30: 0.052 | AA30: 0.318 | AB30: 0.107 | AC30: 0.086 | AD30: 0.032 | AE30: 0.04 | AF30: 0.095 | AG30: 1.8 | AH30: 1.4 | AI30: 1.564 | AJ30: 0.61 | AK30: 5.2 | AL30: 0.7 | AM30: 4
U31: =AVERAGE(U26:U30) -> 16518.14 | V31: =AVERAGE(V26:V30) -> 5384.56 | W31: =AVERAGE(W26:W30) -> 1874.32 | X31: =AVERAGE(X26:X30) -> 1567.94 | Y31: =AVERAGE(Y26:Y30) -> 759.8 | Z31: =AVERAGE(Z26:Z30) -> 0.0216 | AA31: =AVERAGE(AA26:AA30) -> 0.3258 | AB31: =AVERAGE(AB26:AB30) -> 0.1132 | ... AM31: =AVERAGE(AM26:AM30) -> 3.84
